<?xml version="1.0" ?>
<!-- =================================================================================== -->
<!-- |    This document was autogenerated by xacro from base.urdf.xacro                | -->
<!-- |    EDITING THIS FILE BY HAND IS NOT RECOMMENDED                                 | -->
<!-- =================================================================================== -->
<robot name="husky_fei" xmlns:xacro="http://www.ros.org/wiki/xacro">
  <!-- Included URDF/XACRO Files -->
  <material name="Black">
    <color rgba="0.0 0.0 0.0 1.0"/>
  </material>
  <material name="Blue">
    <color rgba="0.0 0.0 0.8 1.0"/>
  </material>
  <material name="Green">
    <color rgba="0.0 0.8 0.0 1.0"/>
  </material>
  <material name="Gray">
    <color rgba="0.7 0.7 0.7 1.0"/>
  </material>
  <material name="DarkGray">
    <color rgba="0.3 0.3 0.3 1.0"/>
  </material>
  <material name="Red">
    <color rgba="0.8 0.0 0.0 1.0"/>
  </material>
  <material name="White">
    <color rgba="1.0 1.0 1.0 1.0"/>
  </material>
  <material name="Yellow">
    <color rgba="0.8 0.8 0.0 1.0"/>
  </material>
  <!-- PROPERTY LIST -->
  <!--All units in m-kg-s-radians unit system -->
  <!-- Main Body-base-->
  <!-- Location of com : center of mass -->
  <!-- Size of the base-->
  <!--Weight of the base-->
  <!-- in kg-->
  <!--Inertial values for the base at center of mass, aligned with coordinate system. Units are kg*m^2-->
  <!-- BASE-FOOTPRINT -->
  <!-- base_footprint is a fictitious link(frame) that is on the ground right below base_link origin, navigation stack depends on this frame -->
  <link name="base_footprint">
    <inertial>
      <mass value="0.0001"/>
      <origin xyz="0 0 0"/>
      <inertia ixx="0.0001" ixy="0.0" ixz="0.0" iyy="0.0001" iyz="0.0" izz="0.0001"/>
    </inertial>
    <visual>
      <origin rpy="0 0 0" xyz="0 0 0"/>
      <geometry>
        <box size="0.001 0.001 0.001"/>
      </geometry>
    </visual>
  </link>
  <gazebo reference="base_footprint">
    <turnGravityOff>false</turnGravityOff>
  </gazebo>
  <joint name="base_footprint_joint" type="fixed">
    <origin rpy="0 0 0" xyz="0 0 0.14492492"/>
    <parent link="base_footprint"/>
    <child link="base_link"/>
  </joint>
  <!-- BASE-LINK -->
  <!--Actual body/chassis of the robot-->
  <link name="base_link">
    <inertial>
      <mass value="33.45489"/>
      <!--This is the pose of the inertial reference frame, relative to the link reference frame. The origin of the inertial reference frame needs to be at the center of gravity. The axes of the inertial reference frame do not need to be aligned with the principal axes of the inertia.-->
      <origin xyz="-0.08748 -0.00085 0.09947"/>
      <!--The 3x3 rotational inertia matrix. Because the rotational inertia matrix is symmetric, only 6 above-diagonal elements of this matrix are specified here, using the attributes ixx, ixy, ixz, iyy, iyz, izz.-->
      <inertia ixx="0.6021637" ixy="-0.02364198" ixz="-0.11972132" iyy="1.73859574" iyz="-0.00154437" izz="2.02955229"/>
    </inertial>
    <visual>
      <origin rpy="0 0 0" xyz="0 0 0"/>
      <geometry>
        <mesh filename="package://husky_fei_description/meshes/base_link.stl"/>
      </geometry>
      <material name="Black"/>
    </visual>
    <collision>
      <origin rpy="0 0 0 " xyz="0 0 0.12492492"/>
      <geometry>
        <box size="1.0074 0.5709 0.2675"/>
        <!--making it slightly bigger in x and z direction-->
      </geometry>
    </collision>
  </link>
  <gazebo reference="base_link">
    <material>Gazebo/FlatBlack</material>
    <turnGravityOff>false</turnGravityOff>
  </gazebo>
  <!-- WHEEL macros -->
  <link name="back_left_wheel">
    <inertial>
      <mass value="2.63657"/>
      <origin xyz="0.0 0.0 0.00019"/>
      <inertia ixx="0.02466885" ixy="0.0" ixz="0.0" iyy="0.02466885" iyz="0.0" izz="0.04410576"/>
    </inertial>
    <visual>
      <origin rpy="-3.14159265359 0 0" xyz="0 0 0"/>
      <geometry>
        <mesh filename="package://husky_fei_description/meshes/wheel.stl"/>
      </geometry>
      <material name="DarkGray"/>
    </visual>
    <collision>
      <origin rpy="-1.57079632679 0 0" xyz="0 0 0"/>
      <geometry>
        <cylinder length="0.1143" radius="0.17775"/>
      </geometry>
    </collision>
  </link>
  <gazebo reference="back_left_wheel">
    <mu1 value="1.0"/>
    <mu2 value="1.0"/>
    <kp value="10000000.0"/>
    <kd value="1.0"/>
    <fdir1 value="1 0 0"/>
    <material>Gazebo/Grey</material>
    <turnGravityOff>false</turnGravityOff>
  </gazebo>
  <joint name="joint_back_left_wheel" type="continuous">
    <parent link="base_link"/>
    <child link="back_left_wheel"/>
    <origin rpy="0 0 0" xyz="-0.25600006 0.285475 0.03282508"/>
    <axis rpy="0 0 0" xyz="0 1 0"/>
    <limit effort="100" velocity="100"/>
    <joint_properties damping="0.0" friction="0.0"/>
  </joint>
  <transmission name="joint_back_left_wheel_trans" type="SimpleTransmission">
    <actuator name="joint_back_left_wheel_motor"/>
    <joint name="joint_back_left_wheel"/>
    <mechanicalReduction>1</mechanicalReduction>
    <motorTorqueConstant>1</motorTorqueConstant>
  </transmission>
  <link name="back_right_wheel">
    <inertial>
      <mass value="2.63657"/>
      <origin xyz="0.0 0.0 0.00019"/>
      <inertia ixx="0.02466885" ixy="0.0" ixz="0.0" iyy="0.02466885" iyz="0.0" izz="0.04410576"/>
    </inertial>
    <visual>
      <origin rpy="-3.14159265359 0 0" xyz="0 0 0"/>
      <geometry>
        <mesh filename="package://husky_fei_description/meshes/wheel.stl"/>
      </geometry>
      <material name="DarkGray"/>
    </visual>
    <collision>
      <origin rpy="-1.57079632679 0 0" xyz="0 0 0"/>
      <geometry>
        <cylinder length="0.1143" radius="0.17775"/>
      </geometry>
    </collision>
  </link>
  <gazebo reference="back_right_wheel">
    <mu1 value="1.0"/>
    <mu2 value="1.0"/>
    <kp value="10000000.0"/>
    <kd value="1.0"/>
    <fdir1 value="1 0 0"/>
    <material>Gazebo/Grey</material>
    <turnGravityOff>false</turnGravityOff>
  </gazebo>
  <joint name="joint_back_right_wheel" type="continuous">
    <parent link="base_link"/>
    <child link="back_right_wheel"/>
    <origin rpy="0 0 0" xyz="-0.25600006 -0.285475 0.03282508"/>
    <axis rpy="0 0 0" xyz="0 1 0"/>
    <limit effort="100" velocity="100"/>
    <joint_properties damping="0.0" friction="0.0"/>
  </joint>
  <transmission name="joint_back_right_wheel_trans" type="SimpleTransmission">
    <actuator name="joint_back_right_wheel_motor"/>
    <joint name="joint_back_right_wheel"/>
    <mechanicalReduction>1</mechanicalReduction>
    <motorTorqueConstant>1</motorTorqueConstant>
  </transmission>
  <link name="front_left_wheel">
    <inertial>
      <mass value="2.63657"/>
      <origin xyz="0.0 0.0 0.00019"/>
      <inertia ixx="0.02466885" ixy="0.0" ixz="0.0" iyy="0.02466885" iyz="0.0" izz="0.04410576"/>
    </inertial>
    <visual>
      <origin rpy="-3.14159265359 0 0" xyz="0 0 0"/>
      <geometry>
        <mesh filename="package://husky_fei_description/meshes/wheel.stl"/>
      </geometry>
      <material name="DarkGray"/>
    </visual>
    <collision>
      <origin rpy="-1.57079632679 0 0" xyz="0 0 0"/>
      <geometry>
        <cylinder length="0.1143" radius="0.17775"/>
      </geometry>
    </collision>
  </link>
  <gazebo reference="front_left_wheel">
    <mu1 value="1.0"/>
    <mu2 value="1.0"/>
    <kp value="10000000.0"/>
    <kd value="1.0"/>
    <fdir1 value="1 0 0"/>
    <material>Gazebo/Grey</material>
    <turnGravityOff>false</turnGravityOff>
  </gazebo>
  <joint name="joint_front_left_wheel" type="continuous">
    <parent link="base_link"/>
    <child link="front_left_wheel"/>
    <origin rpy="0 0 0" xyz="0.25600006 0.285475 0.03282508"/>
    <axis rpy="0 0 0" xyz="0 1 0"/>
    <limit effort="100" velocity="100"/>
    <joint_properties damping="0.0" friction="0.0"/>
  </joint>
  <transmission name="joint_front_left_wheel_trans" type="SimpleTransmission">
    <actuator name="joint_front_left_wheel_motor"/>
    <joint name="joint_front_left_wheel"/>
    <mechanicalReduction>1</mechanicalReduction>
    <motorTorqueConstant>1</motorTorqueConstant>
  </transmission>
  <link name="front_right_wheel">
    <inertial>
      <mass value="2.63657"/>
      <origin xyz="0.0 0.0 0.00019"/>
      <inertia ixx="0.02466885" ixy="0.0" ixz="0.0" iyy="0.02466885" iyz="0.0" izz="0.04410576"/>
    </inertial>
    <visual>
      <origin rpy="-3.14159265359 0 0" xyz="0 0 0"/>
      <geometry>
        <mesh filename="package://husky_fei_description/meshes/wheel.stl"/>
      </geometry>
      <material name="DarkGray"/>
    </visual>
    <collision>
      <origin rpy="-1.57079632679 0 0" xyz="0 0 0"/>
      <geometry>
        <cylinder length="0.1143" radius="0.17775"/>
      </geometry>
    </collision>
  </link>
  <gazebo reference="front_right_wheel">
    <mu1 value="1.0"/>
    <mu2 value="1.0"/>
    <kp value="10000000.0"/>
    <kd value="1.0"/>
    <fdir1 value="1 0 0"/>
    <material>Gazebo/Grey</material>
    <turnGravityOff>false</turnGravityOff>
  </gazebo>
  <joint name="joint_front_right_wheel" type="continuous">
    <parent link="base_link"/>
    <child link="front_right_wheel"/>
    <origin rpy="0 0 0" xyz="0.25600006 -0.285475 0.03282508"/>
    <axis rpy="0 0 0" xyz="0 1 0"/>
    <limit effort="100" velocity="100"/>
    <joint_properties damping="0.0" friction="0.0"/>
  </joint>
  <transmission name="joint_front_right_wheel_trans" type="SimpleTransmission">
    <actuator name="joint_front_right_wheel_motor"/>
    <joint name="joint_front_right_wheel"/>
    <mechanicalReduction>1</mechanicalReduction>
    <motorTorqueConstant>1</motorTorqueConstant>
  </transmission>
  <!-- DECORATIONS -->
  <!-- Top Plate -->
  <link name="base_footprint_top_plate_part">
    <inertial>
      <mass value="0.1"/>
      <origin xyz="0.0 0.0 0.0"/>
      <inertia ixx="0.01" ixy="0.0" ixz="0.0" iyy="0.01" iyz="0.0" izz="0.01"/>
    </inertial>
    <visual>
      <origin rpy="0 0 0" xyz="0 0 0"/>
      <geometry>
        <mesh filename="package://husky_fei_description/meshes/top_plate.stl"/>
      </geometry>
      <material name="Yellow"/>
    </visual>
    <collision>
      <origin rpy="0 0 0" xyz="0 0 0"/>
      <geometry>
        <box size="0.001 0.001 0.001"/>
        <!--the collision boundary for parts are taken into account by collision boundary of the base_link-->
      </geometry>
    </collision>
  </link>
  <joint name="base_footprint_top_plate_joint" type="fixed">
    <origin rpy="0.0 0.0 0.0" xyz="0.0 0.0 0.14492492"/>
    <parent link="base_footprint"/>
    <child link="base_footprint_top_plate_part"/>
  </joint>
  <gazebo reference="base_footprint_top_plate_part">
    <material>Gazebo/Yellow</material>
  </gazebo>
  <!-- User Rail -->
  <link name="base_footprint_user_rail_part">
    <inertial>
      <mass value="0.1"/>
      <origin xyz="0.0 0.0 0.0"/>
      <inertia ixx="0.01" ixy="0.0" ixz="0.0" iyy="0.01" iyz="0.0" izz="0.01"/>
    </inertial>
    <visual>
      <origin rpy="0 0 0" xyz="0 0 0"/>
      <geometry>
        <mesh filename="package://husky_fei_description/meshes/user_rail.stl"/>
      </geometry>
      <material name="DarkGray"/>
    </visual>
    <collision>
      <origin rpy="0 0 0" xyz="0 0 0"/>
      <geometry>
        <box size="0.001 0.001 0.001"/>
        <!--the collision boundary for parts are taken into account by collision boundary of the base_link-->
      </geometry>
    </collision>
  </link>
  <joint name="base_footprint_user_rail_joint" type="fixed">
    <origin rpy="0.0 0.0 0.0" xyz="0.272 0.0 0.38992492"/>
    <parent link="base_footprint"/>
    <child link="base_footprint_user_rail_part"/>
  </joint>
  <gazebo reference="base_footprint_user_rail_part">
    <material>Gazebo/Grey</material>
  </gazebo>
  <!-- My attempt at creating some rails
    <husky_part parent="base_footprint" name="other_rail" mesh="user_rail"
          colour="DarkGray"
          translateX="0.272" translateY="0.0" translateZ="${2*(0.245 + wheel_x_size/2 - base_z_origin_to_wheel_origin)}" 
          rotateX="0.0" rotateY="0.0" rotateZ="0.0"/>
    <gazebo reference="base_footprint_other_rail_part">
        <material>Gazebo/Grey</material>
    </gazebo> -->
  <!-- Bumpers -->
  <link name="base_footprint_front_bumper_part">
    <inertial>
      <mass value="0.1"/>
      <origin xyz="0.0 0.0 0.0"/>
      <inertia ixx="0.01" ixy="0.0" ixz="0.0" iyy="0.01" iyz="0.0" izz="0.01"/>
    </inertial>
    <visual>
      <origin rpy="0 0 0" xyz="0 0 0"/>
      <geometry>
        <mesh filename="package://husky_fei_description/meshes/bumper.stl"/>
      </geometry>
      <material name="DarkGray"/>
    </visual>
    <collision>
      <origin rpy="0 0 0" xyz="0 0 0"/>
      <geometry>
        <box size="0.001 0.001 0.001"/>
        <!--the collision boundary for parts are taken into account by collision boundary of the base_link-->
      </geometry>
    </collision>
  </link>
  <joint name="base_footprint_front_bumper_joint" type="fixed">
    <origin rpy="0.0 0.0 0.0" xyz="0.49 0.0 0.23592492"/>
    <parent link="base_footprint"/>
    <child link="base_footprint_front_bumper_part"/>
  </joint>
  <gazebo reference="base_footprint_front_bumper_part">
    <material>Gazebo/FlatBlack</material>
  </gazebo>
  <link name="base_footprint_rear_bumper_part">
    <inertial>
      <mass value="0.1"/>
      <origin xyz="0.0 0.0 0.0"/>
      <inertia ixx="0.01" ixy="0.0" ixz="0.0" iyy="0.01" iyz="0.0" izz="0.01"/>
    </inertial>
    <visual>
      <origin rpy="0 0 0" xyz="0 0 0"/>
      <geometry>
        <mesh filename="package://husky_fei_description/meshes/bumper.stl"/>
      </geometry>
      <material name="DarkGray"/>
    </visual>
    <collision>
      <origin rpy="0 0 0" xyz="0 0 0"/>
      <geometry>
        <box size="0.001 0.001 0.001"/>
        <!--the collision boundary for parts are taken into account by collision boundary of the base_link-->
      </geometry>
    </collision>
  </link>
  <joint name="base_footprint_rear_bumper_joint" type="fixed">
    <origin rpy="0.0 0.0 3.14" xyz="-0.48 0.0 0.23592492"/>
    <parent link="base_footprint"/>
    <child link="base_footprint_rear_bumper_part"/>
  </joint>
  <gazebo reference="base_footprint_rear_bumper_part">
    <material>Gazebo/FlatBlack</material>
  </gazebo>
  <gazebo>
    <plugin filename="libhusky_gazebo_plugins.so" name="husky_diff_controller">
      <alwaysOn>true</alwaysOn>
      <updateRate>100.0</updateRate>
      <backLeftJoint>joint_back_left_wheel</backLeftJoint>
      <backRightJoint>joint_back_right_wheel</backRightJoint>
      <frontLeftJoint>joint_front_left_wheel</frontLeftJoint>
      <frontRightJoint>joint_front_right_wheel</frontRightJoint>
      <wheelSeparation>0.5709</wheelSeparation>
      <wheelDiameter>0.3555</wheelDiameter>
      <torque>35</torque>
    </plugin>
  </gazebo>
</robot>
