<?xml version="1.0" ?>
<!-- =================================================================================== -->
<!-- |    This document was autogenerated by xacro from husky_fei.urdf.xacro           | -->
<!-- |    EDITING THIS FILE BY HAND IS NOT RECOMMENDED                                 | -->
<!-- =================================================================================== -->
<robot name="husky_fei" xmlns:xacro="http://ros.org/wiki/xacro">
  <!-- Included URDF/XACRO Files -->
  <material name="Black">
    <color rgba="0.0 0.0 0.0 1.0"/>
  </material>
  <material name="Blue">
    <color rgba="0.0 0.0 0.8 1.0"/>
  </material>
  <material name="Green">
    <color rgba="0.0 0.8 0.0 1.0"/>
  </material>
  <material name="Grey">
    <color rgba="0.7 0.7 0.7 1.0"/>
  </material>
  <material name="DarkGrey">
    <color rgba="0.3 0.3 0.3 1.0"/>
  </material>
  <material name="Red">
    <color rgba="0.8 0.0 0.0 1.0"/>
  </material>
  <material name="White">
    <color rgba="1.0 1.0 1.0 1.0"/>
  </material>
  <material name="Yellow">
    <color rgba="0.8 0.8 0.0 1.0"/>
  </material>
  <!-- <xacro:include filename="$(find husky_fei_description)/urdf/sensors/microstrain_3dmgx2_imu.urdf.xacro" /> -->
  <!-- PROPERTY LIST -->
  <!--All units in m-kg-s-radians unit system -->
  <!-- Main Body-base-->
  <!-- Location of com : center of mass -->
  <!-- Size of the base-->
  <!--Weight of the base-->
  <!-- in kg-->
  <!--Inertial values for the base at center of mass, aligned with coordinate system. Units are kg*m^2-->
  <!-- BASE-FOOTPRINT -->
  <!-- base_footprint is a fictitious link(frame) that is on the ground right below base_link origin, navigation stack depends on this frame -->
  <link name="husky_base_footprint">
    <!-- Removing inertial tag due to warning:
        The root link base_footprint has an inertia specified in the URDF, 
        but KDL does not support a root link with an inertia. 
        As a workaround, you can add an extra dummy link to your URDF. -->
    <!--
        <inertial>
            <mass value="0.0001" />
            <origin xyz="0 0 0" />
            <inertia ixx="0.0001" ixy="0.0" ixz="0.0"
                iyy="0.0001" iyz="0.0" 
                izz="0.0001" />
        </inertial>
        -->
    <visual>
      <origin rpy="0 0 0" xyz="0 0 0"/>
      <geometry>
        <box size="0.001 0.001 0.001"/>
      </geometry>
    </visual>
  </link>
  <gazebo reference="husky_base_footprint">
    <turnGravityOff>false</turnGravityOff>
  </gazebo>
  <joint name="husky_base_footprint_joint" type="fixed">
    <origin rpy="0 0 0" xyz="0 0 0.14492492"/>
    <parent link="husky_base_footprint"/>
    <child link="husky_base_link"/>
  </joint>
  <!-- BASE-LINK -->
  <!--Actual body/chassis of the robot-->
  <link name="husky_base_link">
    <inertial>
      <mass value="33.45489"/>
      <!--This is the pose of the inertial reference frame, relative to the link reference frame. The origin of the inertial reference frame needs to be at the center of gravity. The axes of the inertial reference frame do not need to be aligned with the principal axes of the inertia.-->
      <origin xyz="-0.08748 -0.00085 0.09947"/>
      <!--The 3x3 rotational inertia matrix. Because the rotational inertia matrix is symmetric, only 6 above-diagonal elements of this matrix are specified here, using the attributes ixx, ixy, ixz, iyy, iyz, izz.-->
      <inertia ixx="0.6021637" ixy="-0.02364198" ixz="-0.11972132" iyy="1.73859574" iyz="-0.00154437" izz="2.02955229"/>
    </inertial>
    <visual>
      <origin rpy="0 0 0" xyz="0 0 0"/>
      <geometry>
        <mesh filename="package://husky_fei_description/meshes/base_link.stl"/>
      </geometry>
      <material name="Black"/>
    </visual>
    <collision>
      <origin rpy="0 0 0 " xyz="0 0 0.12492492"/>
      <geometry>
        <box size="1.0074 0.5709 0.2675"/>
        <!--making it slightly bigger in x and z direction-->
      </geometry>
    </collision>
  </link>
  <gazebo reference="husky_base_link">
    <material>Gazebo/FlatBlack</material>
    <turnGravityOff>false</turnGravityOff>
  </gazebo>
  <!-- WHEEL macros -->
  <link name="husky_back_left_wheel">
    <inertial>
      <mass value="2.63657"/>
      <origin xyz="0.0 0.0 0.00019"/>
      <inertia ixx="0.02466885" ixy="0.0" ixz="0.0" iyy="0.02466885" iyz="0.0" izz="0.04410576"/>
    </inertial>
    <visual>
      <origin rpy="-3.14159265359 0 0" xyz="0 0 0"/>
      <geometry>
        <mesh filename="package://husky_fei_description/meshes/wheel.stl"/>
      </geometry>
      <material name="DarkGrey"/>
    </visual>
    <collision>
      <origin rpy="-1.57079632679 0 0" xyz="0 0 0"/>
      <geometry>
        <cylinder length="0.1143" radius="0.17775"/>
      </geometry>
    </collision>
  </link>
  <gazebo reference="husky_back_left_wheel">
    <mu1 value="1.0"/>
    <mu2 value="1.0"/>
    <kp value="10000000.0"/>
    <kd value="1.0"/>
    <fdir1 value="1 0 0"/>
    <material>Gazebo/Grey</material>
    <turnGravityOff>false</turnGravityOff>
  </gazebo>
  <joint name="husky_joint_back_left_wheel" type="continuous">
    <parent link="husky_base_link"/>
    <child link="husky_back_left_wheel"/>
    <origin rpy="0 0 0" xyz="-0.25600006 0.285475 0.03282508"/>
    <axis rpy="0 0 0" xyz="0 1 0"/>
    <limit effort="100" velocity="100"/>
    <joint_properties damping="0.0" friction="0.0"/>
  </joint>
  <transmission name="husky_joint_back_left_wheel_trans" type="SimpleTransmission">
    <actuator name="husky_joint_back_left_wheel_motor"/>
    <joint name="husky_joint_back_left_wheel"/>
    <mechanicalReduction>1</mechanicalReduction>
    <motorTorqueConstant>1</motorTorqueConstant>
  </transmission>
  <link name="husky_back_right_wheel">
    <inertial>
      <mass value="2.63657"/>
      <origin xyz="0.0 0.0 0.00019"/>
      <inertia ixx="0.02466885" ixy="0.0" ixz="0.0" iyy="0.02466885" iyz="0.0" izz="0.04410576"/>
    </inertial>
    <visual>
      <origin rpy="-3.14159265359 0 0" xyz="0 0 0"/>
      <geometry>
        <mesh filename="package://husky_fei_description/meshes/wheel.stl"/>
      </geometry>
      <material name="DarkGrey"/>
    </visual>
    <collision>
      <origin rpy="-1.57079632679 0 0" xyz="0 0 0"/>
      <geometry>
        <cylinder length="0.1143" radius="0.17775"/>
      </geometry>
    </collision>
  </link>
  <gazebo reference="husky_back_right_wheel">
    <mu1 value="1.0"/>
    <mu2 value="1.0"/>
    <kp value="10000000.0"/>
    <kd value="1.0"/>
    <fdir1 value="1 0 0"/>
    <material>Gazebo/Grey</material>
    <turnGravityOff>false</turnGravityOff>
  </gazebo>
  <joint name="husky_joint_back_right_wheel" type="continuous">
    <parent link="husky_base_link"/>
    <child link="husky_back_right_wheel"/>
    <origin rpy="0 0 0" xyz="-0.25600006 -0.285475 0.03282508"/>
    <axis rpy="0 0 0" xyz="0 1 0"/>
    <limit effort="100" velocity="100"/>
    <joint_properties damping="0.0" friction="0.0"/>
  </joint>
  <transmission name="husky_joint_back_right_wheel_trans" type="SimpleTransmission">
    <actuator name="husky_joint_back_right_wheel_motor"/>
    <joint name="husky_joint_back_right_wheel"/>
    <mechanicalReduction>1</mechanicalReduction>
    <motorTorqueConstant>1</motorTorqueConstant>
  </transmission>
  <link name="husky_front_left_wheel">
    <inertial>
      <mass value="2.63657"/>
      <origin xyz="0.0 0.0 0.00019"/>
      <inertia ixx="0.02466885" ixy="0.0" ixz="0.0" iyy="0.02466885" iyz="0.0" izz="0.04410576"/>
    </inertial>
    <visual>
      <origin rpy="-3.14159265359 0 0" xyz="0 0 0"/>
      <geometry>
        <mesh filename="package://husky_fei_description/meshes/wheel.stl"/>
      </geometry>
      <material name="DarkGrey"/>
    </visual>
    <collision>
      <origin rpy="-1.57079632679 0 0" xyz="0 0 0"/>
      <geometry>
        <cylinder length="0.1143" radius="0.17775"/>
      </geometry>
    </collision>
  </link>
  <gazebo reference="husky_front_left_wheel">
    <mu1 value="1.0"/>
    <mu2 value="1.0"/>
    <kp value="10000000.0"/>
    <kd value="1.0"/>
    <fdir1 value="1 0 0"/>
    <material>Gazebo/Grey</material>
    <turnGravityOff>false</turnGravityOff>
  </gazebo>
  <joint name="husky_joint_front_left_wheel" type="continuous">
    <parent link="husky_base_link"/>
    <child link="husky_front_left_wheel"/>
    <origin rpy="0 0 0" xyz="0.25600006 0.285475 0.03282508"/>
    <axis rpy="0 0 0" xyz="0 1 0"/>
    <limit effort="100" velocity="100"/>
    <joint_properties damping="0.0" friction="0.0"/>
  </joint>
  <transmission name="husky_joint_front_left_wheel_trans" type="SimpleTransmission">
    <actuator name="husky_joint_front_left_wheel_motor"/>
    <joint name="husky_joint_front_left_wheel"/>
    <mechanicalReduction>1</mechanicalReduction>
    <motorTorqueConstant>1</motorTorqueConstant>
  </transmission>
  <link name="husky_front_right_wheel">
    <inertial>
      <mass value="2.63657"/>
      <origin xyz="0.0 0.0 0.00019"/>
      <inertia ixx="0.02466885" ixy="0.0" ixz="0.0" iyy="0.02466885" iyz="0.0" izz="0.04410576"/>
    </inertial>
    <visual>
      <origin rpy="-3.14159265359 0 0" xyz="0 0 0"/>
      <geometry>
        <mesh filename="package://husky_fei_description/meshes/wheel.stl"/>
      </geometry>
      <material name="DarkGrey"/>
    </visual>
    <collision>
      <origin rpy="-1.57079632679 0 0" xyz="0 0 0"/>
      <geometry>
        <cylinder length="0.1143" radius="0.17775"/>
      </geometry>
    </collision>
  </link>
  <gazebo reference="husky_front_right_wheel">
    <mu1 value="1.0"/>
    <mu2 value="1.0"/>
    <kp value="10000000.0"/>
    <kd value="1.0"/>
    <fdir1 value="1 0 0"/>
    <material>Gazebo/Grey</material>
    <turnGravityOff>false</turnGravityOff>
  </gazebo>
  <joint name="husky_joint_front_right_wheel" type="continuous">
    <parent link="husky_base_link"/>
    <child link="husky_front_right_wheel"/>
    <origin rpy="0 0 0" xyz="0.25600006 -0.285475 0.03282508"/>
    <axis rpy="0 0 0" xyz="0 1 0"/>
    <limit effort="100" velocity="100"/>
    <joint_properties damping="0.0" friction="0.0"/>
  </joint>
  <transmission name="husky_joint_front_right_wheel_trans" type="SimpleTransmission">
    <actuator name="husky_joint_front_right_wheel_motor"/>
    <joint name="husky_joint_front_right_wheel"/>
    <mechanicalReduction>1</mechanicalReduction>
    <motorTorqueConstant>1</motorTorqueConstant>
  </transmission>
  <!-- DECORATIONS -->
  <!-- Top Plate -->
  <link name="husky_base_footprint_top_plate_part">
    <inertial>
      <mass value="0.1"/>
      <origin xyz="0.0 0.0 0.0"/>
      <inertia ixx="0.01" ixy="0.0" ixz="0.0" iyy="0.01" iyz="0.0" izz="0.01"/>
    </inertial>
    <visual>
      <origin rpy="0 0 0" xyz="0 0 0"/>
      <geometry>
        <mesh filename="package://husky_fei_description/meshes/top_plate.stl"/>
      </geometry>
      <material name="Yellow"/>
    </visual>
    <collision>
      <origin rpy="0 0 0" xyz="0 0 0"/>
      <geometry>
        <box size="0.001 0.001 0.001"/>
        <!--the collision boundary for parts are taken into account by collision boundary of the base_link-->
      </geometry>
    </collision>
  </link>
  <joint name="husky_base_footprint_top_plate_joint" type="fixed">
    <origin rpy="0.0 0.0 0.0" xyz="0.0 0.0 0.14492492"/>
    <parent link="husky_base_footprint"/>
    <child link="husky_base_footprint_top_plate_part"/>
  </joint>
  <gazebo reference="husky_base_footprint_top_plate_part">
    <material>Gazebo/Yellow</material>
  </gazebo>
  <!-- User Rail -->
  <link name="husky_base_footprint_user_rail_part">
    <inertial>
      <mass value="0.1"/>
      <origin xyz="0.0 0.0 0.0"/>
      <inertia ixx="0.01" ixy="0.0" ixz="0.0" iyy="0.01" iyz="0.0" izz="0.01"/>
    </inertial>
    <visual>
      <origin rpy="0 0 0" xyz="0 0 0"/>
      <geometry>
        <mesh filename="package://husky_fei_description/meshes/user_rail.stl"/>
      </geometry>
      <material name="DarkGrey"/>
    </visual>
    <collision>
      <origin rpy="0 0 0" xyz="0 0 0"/>
      <geometry>
        <box size="0.001 0.001 0.001"/>
        <!--the collision boundary for parts are taken into account by collision boundary of the base_link-->
      </geometry>
    </collision>
  </link>
  <joint name="husky_base_footprint_user_rail_joint" type="fixed">
    <origin rpy="0.0 0.0 0.0" xyz="0.272 0.0 0.38992492"/>
    <parent link="husky_base_footprint"/>
    <child link="husky_base_footprint_user_rail_part"/>
  </joint>
  <gazebo reference="husky_base_footprint_user_rail_part">
    <material>Gazebo/Grey</material>
  </gazebo>
  <!-- FEI-modded horizontal-front rail -->
  <link name="husky_base_footprint_fei_hf_rail_part">
    <inertial>
      <mass value="0.1"/>
      <origin xyz="0.0 0.0 0.0"/>
      <inertia ixx="0.01" ixy="0.0" ixz="0.0" iyy="0.01" iyz="0.0" izz="0.01"/>
    </inertial>
    <visual>
      <origin rpy="0 0 0" xyz="0 0 0"/>
      <geometry>
        <mesh filename="package://husky_fei_description/meshes/tslot_400x20x20.dae"/>
      </geometry>
      <material name="DarkGrey"/>
    </visual>
    <collision>
      <origin rpy="0 0 0" xyz="0 0 0"/>
      <geometry>
        <box size="0.001 0.001 0.001"/>
        <!--the collision boundary for parts are taken into account by collision boundary of the base_link-->
      </geometry>
    </collision>
  </link>
  <joint name="husky_base_footprint_fei_hf_rail_joint" type="fixed">
    <origin rpy="0.0 0.0 0.0" xyz="0.21 0.0 0.38092492"/>
    <parent link="husky_base_footprint"/>
    <child link="husky_base_footprint_fei_hf_rail_part"/>
  </joint>
  <gazebo reference="husky_base_footprint_fei_hf_rail_part">
    <material>Gazebo/Grey</material>
  </gazebo>
  <!-- FEI-modded horizontal-back rail -->
  <link name="husky_base_footprint_fei_hb_rail_part">
    <inertial>
      <mass value="0.1"/>
      <origin xyz="0.0 0.0 0.0"/>
      <inertia ixx="0.01" ixy="0.0" ixz="0.0" iyy="0.01" iyz="0.0" izz="0.01"/>
    </inertial>
    <visual>
      <origin rpy="0 0 0" xyz="0 0 0"/>
      <geometry>
        <mesh filename="package://husky_fei_description/meshes/tslot_400x20x20.dae"/>
      </geometry>
      <material name="DarkGrey"/>
    </visual>
    <collision>
      <origin rpy="0 0 0" xyz="0 0 0"/>
      <geometry>
        <box size="0.001 0.001 0.001"/>
        <!--the collision boundary for parts are taken into account by collision boundary of the base_link-->
      </geometry>
    </collision>
  </link>
  <joint name="husky_base_footprint_fei_hb_rail_joint" type="fixed">
    <origin rpy="0.0 0.0 0.0" xyz="-0.15 0.0 0.38092492"/>
    <parent link="husky_base_footprint"/>
    <child link="husky_base_footprint_fei_hb_rail_part"/>
  </joint>
  <gazebo reference="husky_base_footprint_fei_hb_rail_part">
    <material>Gazebo/Grey</material>
  </gazebo>
  <!-- FEI-modded vertical-GPS rail -->
  <link name="husky_base_footprint_fei_gps_rail_part">
    <inertial>
      <mass value="0.1"/>
      <origin xyz="0.0 0.0 0.0"/>
      <inertia ixx="0.01" ixy="0.0" ixz="0.0" iyy="0.01" iyz="0.0" izz="0.01"/>
    </inertial>
    <visual>
      <origin rpy="0 0 0" xyz="0 0 0"/>
      <geometry>
        <mesh filename="package://husky_fei_description/meshes/tslot_200x20x20.dae"/>
      </geometry>
      <material name="DarkGrey"/>
    </visual>
    <collision>
      <origin rpy="0 0 0" xyz="0 0 0"/>
      <geometry>
        <box size="0.02 0.02 0.2"/>
      </geometry>
    </collision>
  </link>
  <joint name="husky_base_footprint_fei_gps_rail_joint" type="fixed">
    <origin rpy="0.0 0.0 0.0" xyz="-0.15 0.18 0.49092492"/>
    <parent link="husky_base_footprint"/>
    <child link="husky_base_footprint_fei_gps_rail_part"/>
  </joint>
  <gazebo reference="husky_base_footprint_fei_gps_rail_part">
    <material>Gazebo/Grey</material>
  </gazebo>
  <!-- FEI-modded GPS antenna/module -->
  <link name="husky_gps_link">
    <inertial>
      <mass value="0.10"/>
      <origin xyz="0 0 0"/>
      <inertia ixx="0.000001" ixy="0" ixz="0" iyy="0.000001" iyz="0" izz="0.000001"/>
    </inertial>
    <visual>
      <origin rpy="0 0 0" xyz="0 0 0"/>
      <geometry>
        <mesh filename="package://husky_fei_description/meshes/sensors/GPSAntennaScaledDown.dae"/>
      </geometry>
      <material name="White"/>
    </visual>
    <collision>
      <origin rpy="0 0 0" xyz="0 0 0"/>
      <geometry>
        <box size="0.096 0.096 0.084"/>
      </geometry>
    </collision>
  </link>
  <joint name="husky_gps_joint" type="fixed">
    <parent link="husky_base_link"/>
    <child link="husky_gps_link"/>
    <origin rpy="0.0 0.0 3.14159265359" xyz="-0.151 0.18 0.48392492"/>
  </joint>
  <gazebo>
    <plugin filename="libhector_gazebo_ros_gps.so" name="hector_gazebo_ros_gps_controller">
      <always_on>true</always_on>
      <updateRate>5.0</updateRate>
      <frameId>gps_link</frameId>
      <!-- <bodyName>${name}_link</bodyName> -->
      <bodyName>base_link</bodyName>
      <topicName>gps_fix</topicName>
      <referenceLatitude>37.316357</referenceLatitude>
      <referenceLongitude>141.026065</referenceLongitude>
      <referenceHeading>90</referenceHeading>
      <velocityTopicName>gps_fix_velocity</velocityTopicName>
      <drift>5.0 5.0 5.0</drift>
      <gaussianNoise>0.1 0.1 0.1</gaussianNoise>
      <velocityDrift>0 0 0</velocityDrift>
      <velocityGaussianNoise>0.05 0.05 0.05</velocityGaussianNoise>
    </plugin>
    <plugin filename="libgazebo_ros_p3d.so" name="hector_gazebo_ros_gps_groundtruth_sim">
      <updateRate>100.0</updateRate>
      <bodyName>base_link</bodyName>
      <topicName>ground_truth/state</topicName>
      <gaussianNoise>0.0</gaussianNoise>
      <frameName>world</frameName>
    </plugin>
  </gazebo>
  <gazebo reference="gps_link">
    <material>Gazebo/White</material>
  </gazebo>
  <!-- FEI-modded barometer module -->
  <link name="husky_baro_link">
    <inertial>
      <mass value="0.10"/>
      <origin xyz="0 0 0"/>
      <inertia ixx="0.000001" ixy="0" ixz="0" iyy="0.000001" iyz="0" izz="0.000001"/>
    </inertial>
    <visual>
      <origin rpy="0 0 0" xyz="0 0 0"/>
      <geometry>
        <box size="0.01 0.02 0.02"/>
      </geometry>
      <material name="Red"/>
    </visual>
    <!--
      <collision>
        <origin rpy="0 0 0" xyz="0 0 0"/>
        <geometry>
          <box size="${dimX} ${dimY} ${dimZ}"/>
        </geometry>
      </collision>
-->
  </link>
  <joint name="husky_baro_joint" type="fixed">
    <parent link="husky_base_link"/>
    <child link="husky_baro_link"/>
    <origin rpy="0.0 0.0 0.0" xyz="0.192 -0.05 0.19492492"/>
  </joint>
  <gazebo>
    <plugin filename="libhector_gazebo_ros_baro.so" name="hector_gazebo_ros_baro_controller">
      <alwaysOn>true</alwaysOn>
      <updateRate>10.0</updateRate>
      <bodyName>baro_link</bodyName>
      <frameId>baro_link</frameId>
      <topicName>baro_pressure_height</topicName>
      <altimeterTopicName>baro_altimeter</altimeterTopicName>
      <elevation>0.0</elevation>
      <offset>0</offset>
      <drift>10.0</drift>
      <gaussianNoise>0.1</gaussianNoise>
    </plugin>
  </gazebo>
  <gazebo reference="baro_link">
    <material>Gazebo/Red</material>
  </gazebo>
  <!-- FEI-modded vertical-camera rail -->
  <link name="husky_base_footprint_fei_cam_rail_part">
    <inertial>
      <mass value="0.1"/>
      <origin xyz="0.0 0.0 0.0"/>
      <inertia ixx="0.01" ixy="0.0" ixz="0.0" iyy="0.01" iyz="0.0" izz="0.01"/>
    </inertial>
    <visual>
      <origin rpy="0 0 0" xyz="0 0 0"/>
      <geometry>
        <mesh filename="package://husky_fei_description/meshes/tslot_300x20x20.dae"/>
      </geometry>
      <material name="DarkGrey"/>
    </visual>
    <collision>
      <origin rpy="0 0 0" xyz="0 0 0"/>
      <geometry>
        <box size="0.02 0.02 0.3"/>
      </geometry>
    </collision>
  </link>
  <joint name="husky_base_footprint_fei_cam_rail_joint" type="fixed">
    <origin rpy="0.0 0.0 0.0" xyz="-0.15 0.0 0.54092492"/>
    <parent link="husky_base_footprint"/>
    <child link="husky_base_footprint_fei_cam_rail_part"/>
  </joint>
  <gazebo reference="husky_base_footprint_fei_cam_rail_part">
    <material>Gazebo/Grey</material>
  </gazebo>
  <!-- FEI-modded 3D sensor cam_pz: 0.151 works well too, but must change rail -->
  <joint name="husky_camera_joint" type="fixed">
    <origin rpy="0.0 0.0 0.0" xyz="-0.151 0.0 0.56592492"/>
    <parent link="husky_base_link"/>
    <child link="husky_camera_link"/>
  </joint>
  <link name="husky_camera_link">
    <inertial>
      <mass value="0.001"/>
      <origin xyz="0 0 0.0"/>
      <inertia ixx="0.0001" ixy="0.0" ixz="0.0" iyy="0.0001" iyz="0.0" izz="0.0001"/>
    </inertial>
    <visual>
      <origin rpy="0 0 1.57079632679" xyz="0 0 0.015"/>
      <geometry>
        <mesh filename="package://husky_fei_description/meshes/sensors/kinect.dae"/>
      </geometry>
    </visual>
    <collision>
      <origin rpy="0 0 0" xyz="0.0 0.0 0.0"/>
      <geometry>
        <box size="0.07271 0.27794 0.073"/>
      </geometry>
    </collision>
  </link>
  <joint name="husky_camera_rgb_joint" type="fixed">
    <origin rpy="0 0 0" xyz="0.031 -0.0127 0.031"/>
    <parent link="husky_camera_link"/>
    <child link="husky_camera_rgb_frame"/>
  </joint>
  <link name="husky_camera_rgb_frame">
    <inertial>
      <mass value="0.001"/>
      <origin xyz="0 0 0"/>
      <inertia ixx="0.0001" ixy="0.0" ixz="0.0" iyy="0.0001" iyz="0.0" izz="0.0001"/>
    </inertial>
  </link>
  <joint name="husky_camera_rgb_optical_joint" type="fixed">
    <origin rpy="-1.57079632679 0 -1.57079632679" xyz="0 0 0"/>
    <parent link="husky_camera_rgb_frame"/>
    <child link="husky_camera_rgb_optical_frame"/>
  </joint>
  <link name="husky_camera_rgb_optical_frame">
    <inertial>
      <mass value="0.001"/>
      <origin xyz="0 0 0"/>
      <inertia ixx="0.0001" ixy="0.0" ixz="0.0" iyy="0.0001" iyz="0.0" izz="0.0001"/>
    </inertial>
  </link>
  <joint name="husky_camera_depth_joint" type="fixed">
    <origin rpy="0 0 0" xyz="0.031 +0.0127 0.031"/>
    <parent link="husky_camera_link"/>
    <child link="husky_camera_depth_frame"/>
  </joint>
  <link name="husky_camera_depth_frame">
    <inertial>
      <mass value="0.001"/>
      <origin xyz="0 0 0"/>
      <inertia ixx="0.0001" ixy="0.0" ixz="0.0" iyy="0.0001" iyz="0.0" izz="0.0001"/>
    </inertial>
  </link>
  <joint name="husky_camera_depth_optical_joint" type="fixed">
    <origin rpy="-1.57079632679 0 -1.57079632679" xyz="0 0 0"/>
    <parent link="husky_camera_depth_frame"/>
    <child link="husky_camera_depth_optical_frame"/>
  </joint>
  <link name="husky_camera_depth_optical_frame">
    <inertial>
      <mass value="0.001"/>
      <origin xyz="0 0 0"/>
      <inertia ixx="0.0001" ixy="0.0" ixz="0.0" iyy="0.0001" iyz="0.0" izz="0.0001"/>
    </inertial>
  </link>
  <gazebo reference="camera_depth_frame">
    <sensor name="camera_frame_sensor" type="depth">
      <always_on>true</always_on>
      <update_rate>30.0</update_rate>
      <camera>
        <horizontal_fov>0.994837673637</horizontal_fov>
        <image>
          <format>R8G8B8</format>
          <width>640</width>
          <height>480</height>
        </image>
        <clip>
          <near>0.1</near>
          <far>100.0</far>
        </clip>
      </camera>
      <plugin filename="libgazebo_ros_openni_kinect.so" name="gazebo_ros_camera_controller">
        <cameraName>camera</cameraName>
        <updateRate>30.0</updateRate>
        <imageTopicName>rgb/image_raw</imageTopicName>
        <depthImageTopicName>depth/image_raw</depthImageTopicName>
        <pointCloudTopicName>depth/points</pointCloudTopicName>
        <cameraInfoTopicName>rgb/camera_info</cameraInfoTopicName>
        <depthImageCameraInfoTopicName>depth/camera_info</depthImageCameraInfoTopicName>
        <frameName>camera_depth_optical_frame</frameName>
        <pointCloudCutoff>0.4</pointCloudCutoff>
        <distortion_k1>0.00000001</distortion_k1>
        <distortion_k2>0.00000001</distortion_k2>
        <distortion_k3>0.00000001</distortion_k3>
        <distortion_t1>0.00000001</distortion_t1>
        <distortion_t2>0.00000001</distortion_t2>
        <!-- <baseline>0.2</baseline> -->
      </plugin>
    </sensor>
  </gazebo>
  <!-- FEI-modded vertical-stereo-camera rail -->
  <link name="husky_base_footprint_fei_stereo_rail_part">
    <inertial>
      <mass value="0.1"/>
      <origin xyz="0.0 0.0 0.0"/>
      <inertia ixx="0.01" ixy="0.0" ixz="0.0" iyy="0.01" iyz="0.0" izz="0.01"/>
    </inertial>
    <visual>
      <origin rpy="0 0 0" xyz="0 0 0"/>
      <geometry>
        <mesh filename="package://husky_fei_description/meshes/tslot_500x20x20.dae"/>
      </geometry>
      <material name="DarkGrey"/>
    </visual>
    <collision>
      <origin rpy="0 0 0" xyz="0 0 0"/>
      <geometry>
        <box size="0.02 0.02 0.5"/>
      </geometry>
    </collision>
  </link>
  <joint name="husky_base_footprint_fei_stereo_rail_joint" type="fixed">
    <origin rpy="0.0 0.0 0.0" xyz="-0.24 0.0 0.63092492"/>
    <parent link="husky_base_footprint"/>
    <child link="husky_base_footprint_fei_stereo_rail_part"/>
  </joint>
  <gazebo reference="husky_base_footprint_fei_stereo_rail_part">
    <material>Gazebo/Grey</material>
  </gazebo>
  <!-- FEI-modded multicamera sensor -->
  <joint name="husky_stereo_camera_joint" type="fixed">
    <origin rpy="0.0 0.0 0.0" xyz="-0.24 0.0 0.75092492"/>
    <parent link="husky_base_link"/>
    <child link="husky_stereo_camera_link"/>
  </joint>
  <link name="husky_stereo_camera_link">
    <inertial>
      <mass value="0.01"/>
      <origin xyz="0 0 0"/>
      <inertia ixx="0.0001" ixy="0.0" ixz="0.0" iyy="0.0001" iyz="0.0" izz="0.0001"/>
    </inertial>
    <visual>
      <origin rpy="1.57079632679 0 0" xyz="0 0 0"/>
      <geometry>
        <!-- <box size="0.05 0.1 0.05" /> -->
        <cylinder length="0.1" radius="0.025"/>
      </geometry>
      <material name="Red"/>
      <!--
	<geometry>
          <mesh filename="package://husky_fei_description/meshes/sensors/PS3eye_stereo.dae" />
	</geometry>  
-->
    </visual>
    <collision>
      <origin rpy="0 0 0" xyz="0.0 0.0 0.0"/>
      <geometry>
        <box size="0.06 0.11 0.06"/>
      </geometry>
    </collision>
  </link>
  <joint name="husky_left_camera_joint" type="fixed">
    <origin rpy="0 0 0" xyz="0.030 0.031 0"/>
    <parent link="husky_stereo_camera_link"/>
    <child link="husky_left_camera_frame"/>
  </joint>
  <link name="husky_left_camera_frame">
    <inertial>
      <mass value="0.001"/>
      <origin xyz="0 0 0"/>
      <inertia ixx="0.0001" ixy="0.0" ixz="0.0" iyy="0.0001" iyz="0.0" izz="0.0001"/>
    </inertial>
    <visual>
      <origin rpy="0 1.57079632679 0" xyz="-0.005 0 0"/>
      <geometry>
        <cylinder length="0.01" radius="0.01"/>
      </geometry>
      <material name="Black"/>
    </visual>
  </link>
  <joint name="husky_right_camera_joint" type="fixed">
    <origin rpy="0 0 0" xyz="0.030 -0.031 0"/>
    <parent link="husky_stereo_camera_link"/>
    <child link="husky_right_camera_frame"/>
  </joint>
  <link name="husky_right_camera_frame">
    <inertial>
      <mass value="0.001"/>
      <origin xyz="0 0 0"/>
      <inertia ixx="0.0001" ixy="0.0" ixz="0.0" iyy="0.0001" iyz="0.0" izz="0.0001"/>
    </inertial>
    <visual>
      <origin rpy="0 1.57079632679 0" xyz="-0.005 0 0"/>
      <geometry>
        <cylinder length="0.01" radius="0.01"/>
      </geometry>
      <material name="Black"/>
    </visual>
  </link>
  <gazebo reference="stereo_camera_link">
    <sensor name="stereo_camera" type="multicamera">
      <update_rate>60.0</update_rate>
      <camera name="left">
        <pose>0.030 0.031 0 0 0 0</pose>
        <!-- <horizontal_fov>1.3962634</horizontal_fov> -->
        <horizontal_fov>1.57079632679</horizontal_fov>
        <image>
          <width>640</width>
          <height>800</height>
          <format>R8G8B8</format>
        </image>
        <clip>
          <near>0.02</near>
          <far>300</far>
        </clip>
        <noise>
          <type>gaussian</type>
          <mean>0.0</mean>
          <stddev>0.007</stddev>
        </noise>
      </camera>
      <camera name="right">
        <pose>0.030 -0.031 0 0 0 0</pose>
        <!-- <horizontal_fov>1.3962634</horizontal_fov> -->
        <horizontal_fov>1.57079632679</horizontal_fov>
        <image>
          <width>640</width>
          <height>800</height>
          <format>R8G8B8</format>
        </image>
        <clip>
          <near>0.02</near>
          <far>300</far>
        </clip>
        <noise>
          <type>gaussian</type>
          <mean>0.0</mean>
          <stddev>0.007</stddev>
        </noise>
      </camera>
      <plugin filename="libgazebo_ros_multicamera.so" name="gazebo_ros_stereo_camera_controller">
        <alwaysOn>true</alwaysOn>
        <updateRate>60.0</updateRate>
        <cameraName>stereo_camera</cameraName>
        <imageTopicName>image_raw</imageTopicName>
        <cameraInfoTopicName>stereo_camera_info</cameraInfoTopicName>
        <frameName>left_camera_frame</frameName>
        <hackBaseline>0.062</hackBaseline>
        <distortionK1>0.0</distortionK1>
        <distortionK2>0.0</distortionK2>
        <distortionK3>0.0</distortionK3>
        <distortionT1>0.0</distortionT1>
        <distortionT2>0.0</distortionT2>
      </plugin>
    </sensor>
  </gazebo>
  <gazebo reference="stereo_camera_link">
    <material>Gazebo/Red</material>
  </gazebo>
  <gazebo reference="left_camera_frame">
    <material>Gazebo/Black</material>
  </gazebo>
  <gazebo reference="right_camera_frame">
    <material>Gazebo/Black</material>
  </gazebo>
  <!-- FEI-modded IMU sensor -->
  <!--<sensor_imu name="imu" parent="base" colour="Blue" imu_px="0.192" imu_py="0.0" imu_pz="${0.05 + wheel_x_size/2 - base_z_origin_to_wheel_origin}" imu_or="0.0" imu_op="${M_PI/2.0}" imu_oy="0.0" imu_topic="imu_data" update_rate="100.0" stdev="1.7e-2" /> -->
  <link name="husky_imu_link">
    <inertial>
      <mass value="0.01"/>
      <origin rpy="0 0 0" xyz="0 0 0"/>
      <inertia ixx="0.000001" ixy="0" ixz="0" iyy="0.000001" iyz="0" izz="0.000001"/>
    </inertial>
    <visual>
      <origin rpy="0 0 0" xyz="0 0 0"/>
      <geometry>
        <box size="0.025 0.025 0.01"/>
      </geometry>
      <material name="Blue"/>
    </visual>
    <!--
      <collision>
        <origin rpy="0 0 0" xyz="0 0 0"/>
        <geometry>
          <box size="0.025 0.025 0.01"/>
        </geometry>
      </collision>
-->
  </link>
  <joint name="husky_imu_joint" type="fixed">
    <parent link="husky_base_link"/>
    <child link="husky_imu_link"/>
    <origin rpy="0.0 -1.57079632679 0.0" xyz="0.192 0.0 0.19492492"/>
  </joint>
  <gazebo>
    <plugin filename="libgazebo_ros_imu.so" name="gazebo_ros_imu_controller">
      <always_on>true</always_on>
      <update_rate>100.0</update_rate>
      <bodyName>imu_link</bodyName>
      <topicName>imu_data</topicName>
      <serviceName>imu_service</serviceName>
      <rpyOffset>0 0 0</rpyOffset>
      <gaussianNoise>0</gaussianNoise>
      <accelDrift>0.5 0.5 0.5</accelDrift>
      <accelGaussianNoise>0.35 0.35 0.3</accelGaussianNoise>
      <rateDrift>0.1 0.1 0.1</rateDrift>
      <rateGaussianNoise>0.05 0.05 0.015</rateGaussianNoise>
      <headingDrift>0.1</headingDrift>
      <headingGaussianNoise>0.05</headingGaussianNoise>
    </plugin>
  </gazebo>
  <gazebo reference="imu_link">
    <material>Gazebo/Blue</material>
  </gazebo>
  <!-- FEI-modded Sick LMS100 laser sensor -->
  <joint name="husky_laser_joint" type="fixed">
    <!-- <axis xyz="0 1 0" /> -->
    <origin rpy="0.0 0.0 0" xyz="0.314 0.0 0.28492492"/>
    <parent link="husky_base_link"/>
    <child link="husky_laser_link"/>
  </joint>
  <link name="husky_laser_link" type="laser">
    <inertial>
      <mass value="1.1"/>
      <origin rpy="0 0 0" xyz="0 0 0.05"/>
      <inertia ixx="0.0001" ixy="0" ixz="0" iyy="0.000001" iyz="0" izz="0.0001"/>
    </inertial>
    <collision>
      <origin rpy="0 0 0" xyz="0 0 0.05"/>
      <geometry>
        <box size="0.122 0.104 0.175"/>
      </geometry>
    </collision>
    <visual>
      <origin rpy="0 0 0" xyz="0 0 0.05"/>
      <geometry>
        <mesh filename="package://husky_fei_description/meshes/sensors/LMS100.dae"/>
      </geometry>
    </visual>
  </link>
  <gazebo reference="laser_link">
    <sensor name="laser_lms100_sensor" type="ray">
      <always_on>true</always_on>
      <update_rate>50</update_rate>
      <pose>0 0 0 0 0 0</pose>
      <visualize>false</visualize>
      <ray>
        <scan>
          <horizontal>
            <samples>540</samples>
            <resolution>1</resolution>
            <min_angle>-2.35619449</min_angle>
            <max_angle>2.35619449</max_angle>
          </horizontal>
        </scan>
        <range>
          <min>0.10</min>
          <max>20.0</max>
          <resolution>0.01</resolution>
        </range>
        <noise>
          <type>gaussian</type>
          <!-- Noise parameters based on published spec for Hokuyo laser
                 achieving "+-30mm" accuracy at range < 10m.  A mean of 0.0m and
                 stddev of 0.01m will put 99.7% of samples within 0.03m of the true
                 reading. -->
          <mean>0.0</mean>
          <stddev>0.012</stddev>
        </noise>
      </ray>
      <plugin filename="libgazebo_ros_laser.so" name="gazebo_ros_laser_controller">
        <topicName>laser_data</topicName>
        <frameName>laser_link</frameName>
      </plugin>
    </sensor>
  </gazebo>
  <!-- FEI-modded Sick LMS100 support holder -->
  <link name="husky_base_footprint_lms100_support_part">
    <inertial>
      <mass value="0.1"/>
      <origin xyz="0.0 0.0 0.0"/>
      <inertia ixx="0.01" ixy="0.0" ixz="0.0" iyy="0.01" iyz="0.0" izz="0.01"/>
    </inertial>
    <visual>
      <origin rpy="0 0 0" xyz="0 0 0"/>
      <geometry>
        <mesh filename="package://husky_fei_description/meshes/sensors/LMS100_support_holder.dae"/>
      </geometry>
      <material name="DarkGrey"/>
    </visual>
    <collision>
      <origin rpy="0 0 0" xyz="0 0 0"/>
      <geometry>
        <box size="0.02 0.02 0.1"/>
      </geometry>
    </collision>
  </link>
  <joint name="husky_base_footprint_lms100_support_joint" type="fixed">
    <origin rpy="0.0 0.0 0.0" xyz="0.314 0.0 0.47992492"/>
    <parent link="husky_base_footprint"/>
    <child link="husky_base_footprint_lms100_support_part"/>
  </joint>
  <gazebo reference="husky_base_footprint_lms100_support_part">
    <material>Gazebo/Grey</material>
  </gazebo>
  <!-- FEI-modded Sick LMS100 vertical rails -->
  <link name="husky_base_footprint_fei_lms100_r_rail_part">
    <inertial>
      <mass value="0.1"/>
      <origin xyz="0.0 0.0 0.0"/>
      <inertia ixx="0.01" ixy="0.0" ixz="0.0" iyy="0.01" iyz="0.0" izz="0.01"/>
    </inertial>
    <visual>
      <origin rpy="0 0 0" xyz="0 0 0"/>
      <geometry>
        <mesh filename="package://husky_fei_description/meshes/tslot_100x20x20.dae"/>
      </geometry>
      <material name="DarkGrey"/>
    </visual>
    <collision>
      <origin rpy="0 0 0" xyz="0 0 0"/>
      <geometry>
        <box size="0.02 0.02 0.1"/>
      </geometry>
    </collision>
  </link>
  <joint name="husky_base_footprint_fei_lms100_r_rail_joint" type="fixed">
    <origin rpy="0.0 0.0 0.0" xyz="0.242 0.035 0.42092492"/>
    <parent link="husky_base_footprint"/>
    <child link="husky_base_footprint_fei_lms100_r_rail_part"/>
  </joint>
  <gazebo reference="husky_base_footprint_fei_lms100_r_rail_part">
    <material>Gazebo/Grey</material>
  </gazebo>
  <link name="husky_base_footprint_fei_lms100_l_rail_part">
    <inertial>
      <mass value="0.1"/>
      <origin xyz="0.0 0.0 0.0"/>
      <inertia ixx="0.01" ixy="0.0" ixz="0.0" iyy="0.01" iyz="0.0" izz="0.01"/>
    </inertial>
    <visual>
      <origin rpy="0 0 0" xyz="0 0 0"/>
      <geometry>
        <mesh filename="package://husky_fei_description/meshes/tslot_100x20x20.dae"/>
      </geometry>
      <material name="DarkGrey"/>
    </visual>
    <collision>
      <origin rpy="0 0 0" xyz="0 0 0"/>
      <geometry>
        <box size="0.02 0.02 0.1"/>
      </geometry>
    </collision>
  </link>
  <joint name="husky_base_footprint_fei_lms100_l_rail_joint" type="fixed">
    <origin rpy="0.0 0.0 0.0" xyz="0.242 -0.035 0.42092492"/>
    <parent link="husky_base_footprint"/>
    <child link="husky_base_footprint_fei_lms100_l_rail_part"/>
  </joint>
  <gazebo reference="husky_base_footprint_fei_lms100_l_rail_part">
    <material>Gazebo/Grey</material>
  </gazebo>
  <!-- Bumpers -->
  <link name="husky_base_footprint_front_bumper_part">
    <inertial>
      <mass value="0.1"/>
      <origin xyz="0.0 0.0 0.0"/>
      <inertia ixx="0.01" ixy="0.0" ixz="0.0" iyy="0.01" iyz="0.0" izz="0.01"/>
    </inertial>
    <visual>
      <origin rpy="0 0 0" xyz="0 0 0"/>
      <geometry>
        <mesh filename="package://husky_fei_description/meshes/bumper.stl"/>
      </geometry>
      <material name="DarkGrey"/>
    </visual>
    <collision>
      <origin rpy="0 0 0" xyz="0 0 0"/>
      <geometry>
        <box size="0.001 0.001 0.001"/>
        <!--the collision boundary for parts are taken into account by collision boundary of the base_link-->
      </geometry>
    </collision>
  </link>
  <joint name="husky_base_footprint_front_bumper_joint" type="fixed">
    <origin rpy="0.0 0.0 0.0" xyz="0.49 0.0 0.23592492"/>
    <parent link="husky_base_footprint"/>
    <child link="husky_base_footprint_front_bumper_part"/>
  </joint>
  <gazebo reference="husky_base_footprint_front_bumper_part">
    <material>Gazebo/FlatBlack</material>
  </gazebo>
  <link name="husky_base_footprint_rear_bumper_part">
    <inertial>
      <mass value="0.1"/>
      <origin xyz="0.0 0.0 0.0"/>
      <inertia ixx="0.01" ixy="0.0" ixz="0.0" iyy="0.01" iyz="0.0" izz="0.01"/>
    </inertial>
    <visual>
      <origin rpy="0 0 0" xyz="0 0 0"/>
      <geometry>
        <mesh filename="package://husky_fei_description/meshes/bumper.stl"/>
      </geometry>
      <material name="DarkGrey"/>
    </visual>
    <collision>
      <origin rpy="0 0 0" xyz="0 0 0"/>
      <geometry>
        <box size="0.001 0.001 0.001"/>
        <!--the collision boundary for parts are taken into account by collision boundary of the base_link-->
      </geometry>
    </collision>
  </link>
  <joint name="husky_base_footprint_rear_bumper_joint" type="fixed">
    <origin rpy="0.0 0.0 3.14" xyz="-0.48 0.0 0.23592492"/>
    <parent link="husky_base_footprint"/>
    <child link="husky_base_footprint_rear_bumper_part"/>
  </joint>
  <gazebo reference="husky_base_footprint_rear_bumper_part">
    <material>Gazebo/FlatBlack</material>
  </gazebo>
  <gazebo>
    <plugin filename="libhusky_fei_gazebo_plugins.so" name="husky_diff_controller">
      <alwaysOn>true</alwaysOn>
      <updateRate>100.0</updateRate>
      <backLeftJoint>husky_joint_back_left_wheel</backLeftJoint>
      <backRightJoint>husky_joint_back_right_wheel</backRightJoint>
      <frontLeftJoint>husky_joint_front_left_wheel</frontLeftJoint>
      <frontRightJoint>husky_joint_front_right_wheel</frontRightJoint>
      <wheelSeparation>0.5709</wheelSeparation>
      <wheelDiameter>0.3555</wheelDiameter>
      <torque>35</torque>
    </plugin>
  </gazebo>
</robot>
